<?xml version="1.0"?>
<robot name="my_robot">



    <!--Materials-->
  <material name="blue">
    <color rgba="0 0 0.8 1"/>
  </material>

  <material name="green">
    <color rgba="0 0.8 0. 1"/>
  </material>
  
  <!--Base Link-->
  <link name="base_link">
  </link>
  
  <!--Chassis-->
  <link name="chassis">
    <visual>
      <geometry>
        <box size="0.4 0.4 0.1"/>
      </geometry>
    </visual>
  </link>
  
  <joint name="chassis_joint" type="fixed">
    <parent link="base_link"/>
    <child link="chassis"/>
  </joint>
  

  <!--Front wheel right-->
  <link name="front_wheel_right">
    <visual>
      <geometry>
        <cylinder length="0.04" radius="0.06"/>
      </geometry>
      <material name="blue"/>
    </visual>
  </link>

  <joint name="front_wheel_right_joint" type="continuous">
    <parent link="chassis"/>
    <child link="front_wheel_right"/>
    <origin xyz="0.2 -0.225 0" rpy="1.5707 0 0"/>
    <axis xyz="0 0 -1"/>
  </joint>

  <!--Front wheel left-->
  <link name="front_wheel_left">
    <visual>
      <geometry>
        <cylinder length="0.04" radius="0.06"/>
      </geometry>
      <material name="blue"/>
    </visual>
  </link>

  <joint name="front_wheel_left_joint" type="continuous">
    <parent link="chassis"/>
    <child link="front_wheel_left"/>
    <origin xyz="0.2 0.225 0" rpy="-1.5707 0 0"/>
    <axis xyz="0 0 1"/>
  </joint>

  <!--Rear wheel right-->
  <link name="rear_wheel_right">
    <visual>
      <geometry>
        <cylinder length="0.04" radius="0.06"/>
      </geometry>
      <material name="blue"/>
    </visual>
  </link>

  <joint name="rear_wheel_right_joint" type="continuous">
    <parent link="chassis"/>
    <child link="rear_wheel_right"/>
    <origin xyz="-0.2 -0.225 0" rpy="1.5707 0 0"/>
    <axis xyz="0 0 -1"/>
  </joint>

  <!--Rear wheel left-->
  <link name="rear_wheel_left">
    <visual>
      <geometry>
        <cylinder length="0.04" radius="0.06"/>
      </geometry>
      <material name="blue"/>
    </visual>
  </link>

  <joint name="rear_wheel_left_joint" type="continuous">
    <parent link="chassis"/>
    <child link="rear_wheel_left"/>
    <origin xyz="-0.2 0.225 0" rpy="-1.5707 0 0"/>
    <axis xyz="0 0 1"/>
  </joint>

  

</robot>